[2016-07-29 15:42:30,240] [ERROR] base : Internal Server Error: /blog/artwork/
Traceback (most recent call last):
  File "C:\Python27\lib\site-packages\django-1.8.5-py2.7.egg\django\core\handlers\base.py", line 164, in get_response
    response = response.render()
  File "C:\Python27\lib\site-packages\django-1.8.5-py2.7.egg\django\template\response.py", line 158, in render
    self.content = self.rendered_content
  File "C:\Python27\lib\site-packages\django-1.8.5-py2.7.egg\django\template\response.py", line 133, in rendered_content
    template = self._resolve_template(self.template_name)
  File "C:\Python27\lib\site-packages\django-1.8.5-py2.7.egg\django\template\response.py", line 88, in _resolve_template
    new_template = self.resolve_template(template)
  File "C:\Python27\lib\site-packages\django-1.8.5-py2.7.egg\django\template\response.py", line 78, in resolve_template
    return loader.select_template(template, using=self.using)
  File "C:\Python27\lib\site-packages\django-1.8.5-py2.7.egg\django\template\loader.py", line 78, in select_template
    raise TemplateDoesNotExist("No template names provided")
TemplateDoesNotExist: No template names provided
[2016-07-29 15:42:30,240] [ERROR] base : Internal Server Error: /blog/artwork/
Traceback (most recent call last):
  File "C:\Python27\lib\site-packages\django-1.8.5-py2.7.egg\django\core\handlers\base.py", line 164, in get_response
    response = response.render()
  File "C:\Python27\lib\site-packages\django-1.8.5-py2.7.egg\django\template\response.py", line 158, in render
    self.content = self.rendered_content
  File "C:\Python27\lib\site-packages\django-1.8.5-py2.7.egg\django\template\response.py", line 133, in rendered_content
    template = self._resolve_template(self.template_name)
  File "C:\Python27\lib\site-packages\django-1.8.5-py2.7.egg\django\template\response.py", line 88, in _resolve_template
    new_template = self.resolve_template(template)
  File "C:\Python27\lib\site-packages\django-1.8.5-py2.7.egg\django\template\response.py", line 78, in resolve_template
    return loader.select_template(template, using=self.using)
  File "C:\Python27\lib\site-packages\django-1.8.5-py2.7.egg\django\template\loader.py", line 78, in select_template
    raise TemplateDoesNotExist("No template names provided")
TemplateDoesNotExist: No template names provided
[2016-07-29 15:43:55,286] [ERROR] base : Internal Server Error: /blog/artwork/
Traceback (most recent call last):
  File "C:\Python27\lib\site-packages\django-1.8.5-py2.7.egg\django\core\handlers\base.py", line 132, in get_response
    response = wrapped_callback(request, *callback_args, **callback_kwargs)
  File "C:\Python27\lib\site-packages\django-1.8.5-py2.7.egg\django\views\generic\base.py", line 71, in view
    return self.dispatch(request, *args, **kwargs)
  File "C:\Python27\lib\site-packages\django-1.8.5-py2.7.egg\django\views\generic\base.py", line 89, in dispatch
    return handler(request, *args, **kwargs)
  File "E:\Carcer World\code\Python\git\blog_fx\blog_server\blog\views.py", line 78, in post
    print User.objects.exists(openid_wx = _open_id)
  File "C:\Python27\lib\site-packages\django-1.8.5-py2.7.egg\django\db\models\manager.py", line 127, in manager_method
    return getattr(self.get_queryset(), name)(*args, **kwargs)
TypeError: exists() got an unexpected keyword argument 'openid_wx'
[2016-07-29 15:43:55,286] [ERROR] base : Internal Server Error: /blog/artwork/
Traceback (most recent call last):
  File "C:\Python27\lib\site-packages\django-1.8.5-py2.7.egg\django\core\handlers\base.py", line 132, in get_response
    response = wrapped_callback(request, *callback_args, **callback_kwargs)
  File "C:\Python27\lib\site-packages\django-1.8.5-py2.7.egg\django\views\generic\base.py", line 71, in view
    return self.dispatch(request, *args, **kwargs)
  File "C:\Python27\lib\site-packages\django-1.8.5-py2.7.egg\django\views\generic\base.py", line 89, in dispatch
    return handler(request, *args, **kwargs)
  File "E:\Carcer World\code\Python\git\blog_fx\blog_server\blog\views.py", line 78, in post
    print User.objects.exists(openid_wx = _open_id)
  File "C:\Python27\lib\site-packages\django-1.8.5-py2.7.egg\django\db\models\manager.py", line 127, in manager_method
    return getattr(self.get_queryset(), name)(*args, **kwargs)
TypeError: exists() got an unexpected keyword argument 'openid_wx'
[2016-07-29 15:44:03,736] [ERROR] base : Internal Server Error: /blog/artwork/
Traceback (most recent call last):
  File "C:\Python27\lib\site-packages\django-1.8.5-py2.7.egg\django\core\handlers\base.py", line 132, in get_response
    response = wrapped_callback(request, *callback_args, **callback_kwargs)
  File "C:\Python27\lib\site-packages\django-1.8.5-py2.7.egg\django\views\generic\base.py", line 71, in view
    return self.dispatch(request, *args, **kwargs)
  File "C:\Python27\lib\site-packages\django-1.8.5-py2.7.egg\django\views\generic\base.py", line 89, in dispatch
    return handler(request, *args, **kwargs)
  File "E:\Carcer World\code\Python\git\blog_fx\blog_server\blog\views.py", line 78, in post
    print User.objects.exists(openid_wx = _open_id)
  File "C:\Python27\lib\site-packages\django-1.8.5-py2.7.egg\django\db\models\manager.py", line 127, in manager_method
    return getattr(self.get_queryset(), name)(*args, **kwargs)
TypeError: exists() got an unexpected keyword argument 'openid_wx'
[2016-07-29 15:44:03,736] [ERROR] base : Internal Server Error: /blog/artwork/
Traceback (most recent call last):
  File "C:\Python27\lib\site-packages\django-1.8.5-py2.7.egg\django\core\handlers\base.py", line 132, in get_response
    response = wrapped_callback(request, *callback_args, **callback_kwargs)
  File "C:\Python27\lib\site-packages\django-1.8.5-py2.7.egg\django\views\generic\base.py", line 71, in view
    return self.dispatch(request, *args, **kwargs)
  File "C:\Python27\lib\site-packages\django-1.8.5-py2.7.egg\django\views\generic\base.py", line 89, in dispatch
    return handler(request, *args, **kwargs)
  File "E:\Carcer World\code\Python\git\blog_fx\blog_server\blog\views.py", line 78, in post
    print User.objects.exists(openid_wx = _open_id)
  File "C:\Python27\lib\site-packages\django-1.8.5-py2.7.egg\django\db\models\manager.py", line 127, in manager_method
    return getattr(self.get_queryset(), name)(*args, **kwargs)
TypeError: exists() got an unexpected keyword argument 'openid_wx'
[2016-07-29 15:44:59,155] [ERROR] base : Internal Server Error: /blog/artwork/
Traceback (most recent call last):
  File "C:\Python27\lib\site-packages\django-1.8.5-py2.7.egg\django\core\handlers\base.py", line 151, in get_response
    % (callback.__module__, view_name))
ValueError: The view blog.views.ArtworkView didn't return an HttpResponse object. It returned None instead.
[2016-07-29 15:44:59,155] [ERROR] base : Internal Server Error: /blog/artwork/
Traceback (most recent call last):
  File "C:\Python27\lib\site-packages\django-1.8.5-py2.7.egg\django\core\handlers\base.py", line 151, in get_response
    % (callback.__module__, view_name))
ValueError: The view blog.views.ArtworkView didn't return an HttpResponse object. It returned None instead.
[2016-07-29 15:45:27,881] [ERROR] base : Internal Server Error: /blog/artwork/
Traceback (most recent call last):
  File "C:\Python27\lib\site-packages\django-1.8.5-py2.7.egg\django\core\handlers\base.py", line 151, in get_response
    % (callback.__module__, view_name))
ValueError: The view blog.views.ArtworkView didn't return an HttpResponse object. It returned None instead.
[2016-07-29 15:45:27,881] [ERROR] base : Internal Server Error: /blog/artwork/
Traceback (most recent call last):
  File "C:\Python27\lib\site-packages\django-1.8.5-py2.7.egg\django\core\handlers\base.py", line 151, in get_response
    % (callback.__module__, view_name))
ValueError: The view blog.views.ArtworkView didn't return an HttpResponse object. It returned None instead.
[2016-07-29 15:52:39,384] [ERROR] base : Internal Server Error: /blog/artwork/
Traceback (most recent call last):
  File "C:\Python27\lib\site-packages\django-1.8.5-py2.7.egg\django\core\handlers\base.py", line 132, in get_response
    response = wrapped_callback(request, *callback_args, **callback_kwargs)
  File "C:\Python27\lib\site-packages\django-1.8.5-py2.7.egg\django\views\generic\base.py", line 71, in view
    return self.dispatch(request, *args, **kwargs)
  File "C:\Python27\lib\site-packages\django-1.8.5-py2.7.egg\django\views\generic\base.py", line 89, in dispatch
    return handler(request, *args, **kwargs)
  File "E:\Carcer World\code\Python\git\blog_fx\blog_server\blog\views.py", line 73, in post
    _img_url = self.kwargs.POST.get('img_url', '')
AttributeError: 'dict' object has no attribute 'POST'
[2016-07-29 15:52:39,384] [ERROR] base : Internal Server Error: /blog/artwork/
Traceback (most recent call last):
  File "C:\Python27\lib\site-packages\django-1.8.5-py2.7.egg\django\core\handlers\base.py", line 132, in get_response
    response = wrapped_callback(request, *callback_args, **callback_kwargs)
  File "C:\Python27\lib\site-packages\django-1.8.5-py2.7.egg\django\views\generic\base.py", line 71, in view
    return self.dispatch(request, *args, **kwargs)
  File "C:\Python27\lib\site-packages\django-1.8.5-py2.7.egg\django\views\generic\base.py", line 89, in dispatch
    return handler(request, *args, **kwargs)
  File "E:\Carcer World\code\Python\git\blog_fx\blog_server\blog\views.py", line 73, in post
    _img_url = self.kwargs.POST.get('img_url', '')
AttributeError: 'dict' object has no attribute 'POST'
[2016-07-29 15:53:57,776] [ERROR] base : Internal Server Error: /blog/artwork/
Traceback (most recent call last):
  File "C:\Python27\lib\site-packages\django-1.8.5-py2.7.egg\django\core\handlers\base.py", line 132, in get_response
    response = wrapped_callback(request, *callback_args, **callback_kwargs)
  File "C:\Python27\lib\site-packages\django-1.8.5-py2.7.egg\django\views\generic\base.py", line 71, in view
    return self.dispatch(request, *args, **kwargs)
  File "C:\Python27\lib\site-packages\django-1.8.5-py2.7.egg\django\views\generic\base.py", line 89, in dispatch
    return handler(request, *args, **kwargs)
  File "E:\Carcer World\code\Python\git\blog_fx\blog_server\blog\views.py", line 78, in post
    print User.objects.exists(openid_wx = _open_id)
  File "C:\Python27\lib\site-packages\django-1.8.5-py2.7.egg\django\db\models\manager.py", line 127, in manager_method
    return getattr(self.get_queryset(), name)(*args, **kwargs)
TypeError: exists() got an unexpected keyword argument 'openid_wx'
[2016-07-29 15:53:57,776] [ERROR] base : Internal Server Error: /blog/artwork/
Traceback (most recent call last):
  File "C:\Python27\lib\site-packages\django-1.8.5-py2.7.egg\django\core\handlers\base.py", line 132, in get_response
    response = wrapped_callback(request, *callback_args, **callback_kwargs)
  File "C:\Python27\lib\site-packages\django-1.8.5-py2.7.egg\django\views\generic\base.py", line 71, in view
    return self.dispatch(request, *args, **kwargs)
  File "C:\Python27\lib\site-packages\django-1.8.5-py2.7.egg\django\views\generic\base.py", line 89, in dispatch
    return handler(request, *args, **kwargs)
  File "E:\Carcer World\code\Python\git\blog_fx\blog_server\blog\views.py", line 78, in post
    print User.objects.exists(openid_wx = _open_id)
  File "C:\Python27\lib\site-packages\django-1.8.5-py2.7.egg\django\db\models\manager.py", line 127, in manager_method
    return getattr(self.get_queryset(), name)(*args, **kwargs)
TypeError: exists() got an unexpected keyword argument 'openid_wx'
[2016-07-29 16:15:40,397] [ERROR] base : Internal Server Error: /blog/gallery/12
Traceback (most recent call last):
  File "C:\Python27\lib\site-packages\django-1.8.5-py2.7.egg\django\core\handlers\base.py", line 132, in get_response
    response = wrapped_callback(request, *callback_args, **callback_kwargs)
  File "C:\Python27\lib\site-packages\django-1.8.5-py2.7.egg\django\views\generic\base.py", line 71, in view
    return self.dispatch(request, *args, **kwargs)
  File "C:\Python27\lib\site-packages\django-1.8.5-py2.7.egg\django\views\generic\base.py", line 89, in dispatch
    return handler(request, *args, **kwargs)
  File "E:\Carcer World\code\Python\git\blog_fx\blog_server\blog\views.py", line 65, in get
    return super(GalleryView, self).get(request, *args, **kwargs)
  File "C:\Python27\lib\site-packages\django-1.8.5-py2.7.egg\django\views\generic\list.py", line 159, in get
    self.object_list = self.get_queryset()
  File "E:\Carcer World\code\Python\git\blog_fx\blog_server\blog\views.py", line 58, in get_queryset
    gallery = Gallery.objects.filter(openid_wx=_open_id)
  File "C:\Python27\lib\site-packages\django-1.8.5-py2.7.egg\django\db\models\manager.py", line 127, in manager_method
    return getattr(self.get_queryset(), name)(*args, **kwargs)
  File "C:\Python27\lib\site-packages\django-1.8.5-py2.7.egg\django\db\models\query.py", line 679, in filter
    return self._filter_or_exclude(False, *args, **kwargs)
  File "C:\Python27\lib\site-packages\django-1.8.5-py2.7.egg\django\db\models\query.py", line 697, in _filter_or_exclude
    clone.query.add_q(Q(*args, **kwargs))
  File "C:\Python27\lib\site-packages\django-1.8.5-py2.7.egg\django\db\models\sql\query.py", line 1310, in add_q
    clause, require_inner = self._add_q(where_part, self.used_aliases)
  File "C:\Python27\lib\site-packages\django-1.8.5-py2.7.egg\django\db\models\sql\query.py", line 1338, in _add_q
    allow_joins=allow_joins, split_subq=split_subq,
  File "C:\Python27\lib\site-packages\django-1.8.5-py2.7.egg\django\db\models\sql\query.py", line 1150, in build_filter
    lookups, parts, reffed_expression = self.solve_lookup_type(arg)
  File "C:\Python27\lib\site-packages\django-1.8.5-py2.7.egg\django\db\models\sql\query.py", line 1036, in solve_lookup_type
    _, field, _, lookup_parts = self.names_to_path(lookup_splitted, self.get_meta())
  File "C:\Python27\lib\site-packages\django-1.8.5-py2.7.egg\django\db\models\sql\query.py", line 1397, in names_to_path
    "Choices are: %s" % (name, ", ".join(available)))
FieldError: Cannot resolve keyword 'openid_wx' into field. Choices are: char_img_url, create_time, id, img_url, user, user_id
[2016-07-29 16:15:40,397] [ERROR] base : Internal Server Error: /blog/gallery/12
Traceback (most recent call last):
  File "C:\Python27\lib\site-packages\django-1.8.5-py2.7.egg\django\core\handlers\base.py", line 132, in get_response
    response = wrapped_callback(request, *callback_args, **callback_kwargs)
  File "C:\Python27\lib\site-packages\django-1.8.5-py2.7.egg\django\views\generic\base.py", line 71, in view
    return self.dispatch(request, *args, **kwargs)
  File "C:\Python27\lib\site-packages\django-1.8.5-py2.7.egg\django\views\generic\base.py", line 89, in dispatch
    return handler(request, *args, **kwargs)
  File "E:\Carcer World\code\Python\git\blog_fx\blog_server\blog\views.py", line 65, in get
    return super(GalleryView, self).get(request, *args, **kwargs)
  File "C:\Python27\lib\site-packages\django-1.8.5-py2.7.egg\django\views\generic\list.py", line 159, in get
    self.object_list = self.get_queryset()
  File "E:\Carcer World\code\Python\git\blog_fx\blog_server\blog\views.py", line 58, in get_queryset
    gallery = Gallery.objects.filter(openid_wx=_open_id)
  File "C:\Python27\lib\site-packages\django-1.8.5-py2.7.egg\django\db\models\manager.py", line 127, in manager_method
    return getattr(self.get_queryset(), name)(*args, **kwargs)
  File "C:\Python27\lib\site-packages\django-1.8.5-py2.7.egg\django\db\models\query.py", line 679, in filter
    return self._filter_or_exclude(False, *args, **kwargs)
  File "C:\Python27\lib\site-packages\django-1.8.5-py2.7.egg\django\db\models\query.py", line 697, in _filter_or_exclude
    clone.query.add_q(Q(*args, **kwargs))
  File "C:\Python27\lib\site-packages\django-1.8.5-py2.7.egg\django\db\models\sql\query.py", line 1310, in add_q
    clause, require_inner = self._add_q(where_part, self.used_aliases)
  File "C:\Python27\lib\site-packages\django-1.8.5-py2.7.egg\django\db\models\sql\query.py", line 1338, in _add_q
    allow_joins=allow_joins, split_subq=split_subq,
  File "C:\Python27\lib\site-packages\django-1.8.5-py2.7.egg\django\db\models\sql\query.py", line 1150, in build_filter
    lookups, parts, reffed_expression = self.solve_lookup_type(arg)
  File "C:\Python27\lib\site-packages\django-1.8.5-py2.7.egg\django\db\models\sql\query.py", line 1036, in solve_lookup_type
    _, field, _, lookup_parts = self.names_to_path(lookup_splitted, self.get_meta())
  File "C:\Python27\lib\site-packages\django-1.8.5-py2.7.egg\django\db\models\sql\query.py", line 1397, in names_to_path
    "Choices are: %s" % (name, ", ".join(available)))
FieldError: Cannot resolve keyword 'openid_wx' into field. Choices are: char_img_url, create_time, id, img_url, user, user_id
[2016-07-29 16:15:56,618] [ERROR] base : Internal Server Error: /blog/gallery/11
Traceback (most recent call last):
  File "C:\Python27\lib\site-packages\django-1.8.5-py2.7.egg\django\core\handlers\base.py", line 132, in get_response
    response = wrapped_callback(request, *callback_args, **callback_kwargs)
  File "C:\Python27\lib\site-packages\django-1.8.5-py2.7.egg\django\views\generic\base.py", line 71, in view
    return self.dispatch(request, *args, **kwargs)
  File "C:\Python27\lib\site-packages\django-1.8.5-py2.7.egg\django\views\generic\base.py", line 89, in dispatch
    return handler(request, *args, **kwargs)
  File "E:\Carcer World\code\Python\git\blog_fx\blog_server\blog\views.py", line 65, in get
    return super(GalleryView, self).get(request, *args, **kwargs)
  File "C:\Python27\lib\site-packages\django-1.8.5-py2.7.egg\django\views\generic\list.py", line 159, in get
    self.object_list = self.get_queryset()
  File "E:\Carcer World\code\Python\git\blog_fx\blog_server\blog\views.py", line 58, in get_queryset
    gallery = Gallery.objects.filter(openid_wx=_open_id)
  File "C:\Python27\lib\site-packages\django-1.8.5-py2.7.egg\django\db\models\manager.py", line 127, in manager_method
    return getattr(self.get_queryset(), name)(*args, **kwargs)
  File "C:\Python27\lib\site-packages\django-1.8.5-py2.7.egg\django\db\models\query.py", line 679, in filter
    return self._filter_or_exclude(False, *args, **kwargs)
  File "C:\Python27\lib\site-packages\django-1.8.5-py2.7.egg\django\db\models\query.py", line 697, in _filter_or_exclude
    clone.query.add_q(Q(*args, **kwargs))
  File "C:\Python27\lib\site-packages\django-1.8.5-py2.7.egg\django\db\models\sql\query.py", line 1310, in add_q
    clause, require_inner = self._add_q(where_part, self.used_aliases)
  File "C:\Python27\lib\site-packages\django-1.8.5-py2.7.egg\django\db\models\sql\query.py", line 1338, in _add_q
    allow_joins=allow_joins, split_subq=split_subq,
  File "C:\Python27\lib\site-packages\django-1.8.5-py2.7.egg\django\db\models\sql\query.py", line 1150, in build_filter
    lookups, parts, reffed_expression = self.solve_lookup_type(arg)
  File "C:\Python27\lib\site-packages\django-1.8.5-py2.7.egg\django\db\models\sql\query.py", line 1036, in solve_lookup_type
    _, field, _, lookup_parts = self.names_to_path(lookup_splitted, self.get_meta())
  File "C:\Python27\lib\site-packages\django-1.8.5-py2.7.egg\django\db\models\sql\query.py", line 1397, in names_to_path
    "Choices are: %s" % (name, ", ".join(available)))
FieldError: Cannot resolve keyword 'openid_wx' into field. Choices are: char_img_url, create_time, id, img_url, user, user_id
[2016-07-29 16:15:56,618] [ERROR] base : Internal Server Error: /blog/gallery/11
Traceback (most recent call last):
  File "C:\Python27\lib\site-packages\django-1.8.5-py2.7.egg\django\core\handlers\base.py", line 132, in get_response
    response = wrapped_callback(request, *callback_args, **callback_kwargs)
  File "C:\Python27\lib\site-packages\django-1.8.5-py2.7.egg\django\views\generic\base.py", line 71, in view
    return self.dispatch(request, *args, **kwargs)
  File "C:\Python27\lib\site-packages\django-1.8.5-py2.7.egg\django\views\generic\base.py", line 89, in dispatch
    return handler(request, *args, **kwargs)
  File "E:\Carcer World\code\Python\git\blog_fx\blog_server\blog\views.py", line 65, in get
    return super(GalleryView, self).get(request, *args, **kwargs)
  File "C:\Python27\lib\site-packages\django-1.8.5-py2.7.egg\django\views\generic\list.py", line 159, in get
    self.object_list = self.get_queryset()
  File "E:\Carcer World\code\Python\git\blog_fx\blog_server\blog\views.py", line 58, in get_queryset
    gallery = Gallery.objects.filter(openid_wx=_open_id)
  File "C:\Python27\lib\site-packages\django-1.8.5-py2.7.egg\django\db\models\manager.py", line 127, in manager_method
    return getattr(self.get_queryset(), name)(*args, **kwargs)
  File "C:\Python27\lib\site-packages\django-1.8.5-py2.7.egg\django\db\models\query.py", line 679, in filter
    return self._filter_or_exclude(False, *args, **kwargs)
  File "C:\Python27\lib\site-packages\django-1.8.5-py2.7.egg\django\db\models\query.py", line 697, in _filter_or_exclude
    clone.query.add_q(Q(*args, **kwargs))
  File "C:\Python27\lib\site-packages\django-1.8.5-py2.7.egg\django\db\models\sql\query.py", line 1310, in add_q
    clause, require_inner = self._add_q(where_part, self.used_aliases)
  File "C:\Python27\lib\site-packages\django-1.8.5-py2.7.egg\django\db\models\sql\query.py", line 1338, in _add_q
    allow_joins=allow_joins, split_subq=split_subq,
  File "C:\Python27\lib\site-packages\django-1.8.5-py2.7.egg\django\db\models\sql\query.py", line 1150, in build_filter
    lookups, parts, reffed_expression = self.solve_lookup_type(arg)
  File "C:\Python27\lib\site-packages\django-1.8.5-py2.7.egg\django\db\models\sql\query.py", line 1036, in solve_lookup_type
    _, field, _, lookup_parts = self.names_to_path(lookup_splitted, self.get_meta())
  File "C:\Python27\lib\site-packages\django-1.8.5-py2.7.egg\django\db\models\sql\query.py", line 1397, in names_to_path
    "Choices are: %s" % (name, ", ".join(available)))
FieldError: Cannot resolve keyword 'openid_wx' into field. Choices are: char_img_url, create_time, id, img_url, user, user_id
[2016-07-29 16:22:32,371] [ERROR] base : Internal Server Error: /blog/gallery/11
Traceback (most recent call last):
  File "C:\Python27\lib\site-packages\django-1.8.5-py2.7.egg\django\core\handlers\base.py", line 132, in get_response
    response = wrapped_callback(request, *callback_args, **callback_kwargs)
  File "C:\Python27\lib\site-packages\django-1.8.5-py2.7.egg\django\views\generic\base.py", line 71, in view
    return self.dispatch(request, *args, **kwargs)
  File "C:\Python27\lib\site-packages\django-1.8.5-py2.7.egg\django\views\generic\base.py", line 89, in dispatch
    return handler(request, *args, **kwargs)
  File "E:\Carcer World\code\Python\git\blog_fx\blog_server\blog\views.py", line 72, in get
    return super(GalleryView, self).get(request, *args, **kwargs)
  File "C:\Python27\lib\site-packages\django-1.8.5-py2.7.egg\django\views\generic\list.py", line 159, in get
    self.object_list = self.get_queryset()
  File "E:\Carcer World\code\Python\git\blog_fx\blog_server\blog\views.py", line 63, in get_queryset
    print gallery.user
AttributeError: 'QuerySet' object has no attribute 'user'
[2016-07-29 16:22:32,371] [ERROR] base : Internal Server Error: /blog/gallery/11
Traceback (most recent call last):
  File "C:\Python27\lib\site-packages\django-1.8.5-py2.7.egg\django\core\handlers\base.py", line 132, in get_response
    response = wrapped_callback(request, *callback_args, **callback_kwargs)
  File "C:\Python27\lib\site-packages\django-1.8.5-py2.7.egg\django\views\generic\base.py", line 71, in view
    return self.dispatch(request, *args, **kwargs)
  File "C:\Python27\lib\site-packages\django-1.8.5-py2.7.egg\django\views\generic\base.py", line 89, in dispatch
    return handler(request, *args, **kwargs)
  File "E:\Carcer World\code\Python\git\blog_fx\blog_server\blog\views.py", line 72, in get
    return super(GalleryView, self).get(request, *args, **kwargs)
  File "C:\Python27\lib\site-packages\django-1.8.5-py2.7.egg\django\views\generic\list.py", line 159, in get
    self.object_list = self.get_queryset()
  File "E:\Carcer World\code\Python\git\blog_fx\blog_server\blog\views.py", line 63, in get_queryset
    print gallery.user
AttributeError: 'QuerySet' object has no attribute 'user'
[2016-07-29 16:24:34,575] [ERROR] base : Internal Server Error: /blog/gallery/11
Traceback (most recent call last):
  File "C:\Python27\lib\site-packages\django-1.8.5-py2.7.egg\django\core\handlers\base.py", line 132, in get_response
    response = wrapped_callback(request, *callback_args, **callback_kwargs)
  File "C:\Python27\lib\site-packages\django-1.8.5-py2.7.egg\django\views\generic\base.py", line 71, in view
    return self.dispatch(request, *args, **kwargs)
  File "C:\Python27\lib\site-packages\django-1.8.5-py2.7.egg\django\views\generic\base.py", line 89, in dispatch
    return handler(request, *args, **kwargs)
  File "E:\Carcer World\code\Python\git\blog_fx\blog_server\blog\views.py", line 72, in get
    class ArtworkView(BaseMixin, ListView):
  File "C:\Python27\lib\site-packages\django-1.8.5-py2.7.egg\django\views\generic\list.py", line 159, in get
    self.object_list = self.get_queryset()
  File "E:\Carcer World\code\Python\git\blog_fx\blog_server\blog\views.py", line 63, in get_queryset
    
AttributeError: 'QuerySet' object has no attribute 'user'
[2016-07-29 16:24:34,575] [ERROR] base : Internal Server Error: /blog/gallery/11
Traceback (most recent call last):
  File "C:\Python27\lib\site-packages\django-1.8.5-py2.7.egg\django\core\handlers\base.py", line 132, in get_response
    response = wrapped_callback(request, *callback_args, **callback_kwargs)
  File "C:\Python27\lib\site-packages\django-1.8.5-py2.7.egg\django\views\generic\base.py", line 71, in view
    return self.dispatch(request, *args, **kwargs)
  File "C:\Python27\lib\site-packages\django-1.8.5-py2.7.egg\django\views\generic\base.py", line 89, in dispatch
    return handler(request, *args, **kwargs)
  File "E:\Carcer World\code\Python\git\blog_fx\blog_server\blog\views.py", line 72, in get
    class ArtworkView(BaseMixin, ListView):
  File "C:\Python27\lib\site-packages\django-1.8.5-py2.7.egg\django\views\generic\list.py", line 159, in get
    self.object_list = self.get_queryset()
  File "E:\Carcer World\code\Python\git\blog_fx\blog_server\blog\views.py", line 63, in get_queryset
    
AttributeError: 'QuerySet' object has no attribute 'user'
